Workbook

Sheet 能力地图
A1: 地图ID | B1: 地图名称 | C1: 品类编码（全品类编码） | D1: 品类名称 | E1: 品类编码（全品类编码） | F1: A级描述 | G1: B级描述 | H1: C级描述
A2: 227 | B2: CO/PICCO附件-选型沙盘 | C2: =VLOOKUP(D2,[1]品类分类!$F:$G,2,FALSE) -> 001400020007 | D2: CO/PICCO附件 | E2: 001400020007 | F2: 产品量产>1年 | G2: 产品未量产上市 | H2: 没有类似产品
A3: 228 | B3: ICG/FLOTRAC附件-选型沙盘 | C3: =VLOOKUP(D3,[1]品类分类!$F:$G,2,FALSE) -> 001400020008 | D3: ICG/FLOTRAC附件 | E3: 001400020008 | F3: 产品量产>1年 | G3: 产品未量产上市 | H3: 没有类似产品
A4: 229 | B4: 疼痛参数附件-选型沙盘 | C4: =VLOOKUP(D4,[1]品类分类!$F:$G,2,FALSE) -> 001400020009 | D4: 疼痛参数附件 | E4: 001400020009 | F4: 产品量产>1年 | G4: 产品未量产上市 | H4: 没有类似产品
A5: 230 | B5: CO2附件-选型沙盘 | C5: =VLOOKUP(D5,[1]品类分类!$F:$G,2,FALSE) -> 001400020010 | D5: CO2附件 | E5: 001400020010 | F5: 产品量产>1年 | G5: 产品未量产上市 | H5: 没有类似产品
A6: 231 | B6: ISE电解质模块及附件-选型沙盘 | C6: =VLOOKUP(D6,[1]品类分类!$F:$G,2,FALSE) -> 001400020011 | D6: ISE电解质模块及附件 | E6: 001400020011 | F6: 产品量产>1年 | G6: 产品未量产上市 | H6: 没有类似产品
A7: 233 | B7: 探头声头附件-选型沙盘 | C7: =VLOOKUP(D7,[1]品类分类!$F:$G,2,FALSE) -> 001400030002 | D7: 探头声头附件 | E7: 001400030002 | F7: 产品已量产 | G7: 产品未量产上市 | H7: 没有类似产品
A8: 237 | B8: 外科手术器械附件-选型沙盘 | C8: =VLOOKUP(D8,[1]品类分类!$F:$G,2,FALSE) -> 001400050002 | D8: 外科手术器械附件 | E8: 001400050002 | F8: 产品已量产 | G8: 产品未量产上市 | H8: 没有类似产品
A9: 238 | B9: 整机-选型沙盘 | C9: =VLOOKUP(D9,[1]品类分类!$F:$G,2,FALSE) -> 001400060001 | D9: 整机 | E9: 001400060001 | F9: 产品量产>1年 | G9: 产品未量产上市 | H9: 没有类似产品
A10: 239 | B10: 整机配套附件-选型沙盘 | C10: =VLOOKUP(D10,[1]品类分类!$F:$G,2,FALSE) -> 001400060002 | D10: 整机配套附件 | E10: 001400060002 | F10: 产品量产>1年 | G10: 产品未量产上市 | H10: 没有类似产品
A11: 346 | B11: 多抗-选型沙盘 | C11: 002400010001 | D11: 多抗 | E11: 002400010001 | F11: 有，厂家优势产品 | G11: 有，常规产品 | H11: 无此产品
A12: 347 | B12: 天然抗原-选型沙盘 | C12: 002400010002 | D12: 天然抗原 | E12: 002400010002 | F12: 有，厂家优势产品 | G12: 有，常规产品 | H12: 无此产品
A13: 348 | B13: 单抗-选型沙盘 | C13: 002400010003 | D13: 单抗 | E13: 002400010003 | F13: 有，厂家优势产品 | G13: 有，常规产品 | H13: 无此产品
A14: 349 | B14: 重组抗原-选型沙盘 | C14: 002400010004 | D14: 重组抗原 | E14: 002400010004 | F14: 有，厂家优势产品 | G14: 有，常规产品 | H14: 无此产品
A15: 350 | B15: 酶-选型沙盘 | C15: 002400020001 | D15: 酶 | E15: 002400020001 | F15: 有，厂家优势产品 | G15: 有，常规产品 | H15: 无此产品
A16: 351 | B16: 阻断剂/稳定剂-选型沙盘 | C16: 002400030001 | D16: 阻断剂/稳定剂 | E16: 002400030001 | F16: 有，厂家优势产品 | G16: 有，常规产品 | H16: 无此产品
A17: 352 | B17: BSA-选型沙盘 | C17: 002400030002 | D17: BSA | E17: 002400030002 | F17: 有，厂家优势产品 | G17: 有，常规产品 | H17: 无此产品
A18: 353 | B18: 质控校准原料-选型沙盘 | C18: 002400040001 | D18: 质控校准原料 | E18: 002400040001 | F18: 有，厂家优势产品 | G18: 有，常规产品 | H18: 无此产品
A19: 354 | B19: 生物耗材-选型沙盘 | C19: 002400050001 | D19: 生物耗材 | E19: 002400050001 | F19: 有，厂家优势产品 | G19: 有，常规产品 | H19: 无此产品
A20: 355 | B20: 表面活性剂-选型沙盘 | C20: 002500010001 | D20: 表面活性剂 | E20: 002500010001 | F20: 有，厂家优势产品 | G20: 有，常规产品 | H20: 无此产品
A21: 356 | B21: 抑菌剂-选型沙盘 | C21: 002500020001 | D21: 抑菌剂 | E21: 002500020001 | F21: 有，厂家优势产品 | G21: 有，常规产品 | H21: 无此产品
A22: 357 | B22: 活性化学试剂-选型沙盘 | C22: 002500030001 | D22: 活性化学试剂 | E22: 002500030001 | F22: 有，厂家优势产品 | G22: 有，常规产品 | H22: 无此产品
... A28: 176 | B28: 柱塞泵-选型沙盘 | C28: 001200010003 | D28: 柱塞泵 | E28: 001200010003 | F28: 产品量产﹥1年 | G28: 产品正在开发中 | H28: 没有类似产品
A29: 278 | B29: 螺钉/螺栓-选型沙盘 | C29: =VLOOKUP(D29,[2]品类分类!$F:$G,2,FALSE) -> 001700010001 | D29: 螺钉/螺栓 | E29: 001700010001 | F29: 产品量产>1年 | G29: 产品正在开发中 | H29: 没有类似产品
A30: 279 | B30: 组合螺钉-选型沙盘 | C30: =VLOOKUP(D30,[2]品类分类!$F:$G,2,FALSE) -> 001700010002 | D30: 组合螺钉 | E30: 001700010002 | F30: 产品量产>1年 | G30: 产品正在开发中 | H30: 没有类似产品
A31: 280 | B31: 螺母-选型沙盘 | C31: =VLOOKUP(D31,[2]品类分类!$F:$G,2,FALSE) -> 001700010003 | D31: 螺母 | E31: 001700010003 | F31: 产品量产>1年 | G31: 产品正在开发中 | H31: 没有类似产品
A32: 281 | B32: 垫圈/挡圈-选型沙盘 | C32: =VLOOKUP(D32,[2]品类分类!$F:$G,2,FALSE) -> 001700010004 | D32: 垫圈/挡圈 | E32: 001700010004 | F32: 产品量产>1年 | G32: 产品正在开发中 | H32: 没有类似产品
A33: 282 | B33: 螺柱/铆钉-选型沙盘 | C33: =VLOOKUP(D33,[2]品类分类!$F:$G,2,FALSE) -> 001700010005 | D33: 螺柱/铆钉 | E33: 001700010005 | F33: 产品量产>1年 | G33: 产品正在开发中 | H33: 没有类似产品
A34: 283 | B34: 定位件-选型沙盘 | C34: =VLOOKUP(D34,[2]品类分类!$F:$G,2,FALSE) -> 001700010006 | D34: 定位件 | E34: 001700010006 | F34: 产品量产>1年 | G34: 产品正在开发中 | H34: 没有类似产品
A35: 284 | B35: 定制紧固件-选型沙盘 | C35: =VLOOKUP(D35,[2]品类分类!$F:$G,2,FALSE) -> 001700010007 | D35: 定制紧固件 | E35: 001700010007 | F35: 产品量产>1年 | G35: 产品正在开发中 | H35: 没有类似产品
A36: 285 | B36: 螺线弹簧-选型沙盘 | C36: =VLOOKUP(D36,[2]品类分类!$F:$G,2,FALSE) -> 001700020001 | D36: 螺线弹簧 | E36: 001700020001 | F36: 产品量产>1年 | G36: 产品正在开发中 | H36: 没有类似产品
A37: 286 | B37: 特种弹簧-选型沙盘 | C37: =VLOOKUP(D37,[2]品类分类!$F:$G,2,FALSE) -> 001700020002 | D37: 特种弹簧 | E37: 001700020002 | F37: 产品量产>1年 | G37: 产品正在开发中 | H37: 没有类似产品
A38: 287 | B38: 直线传动件-选型沙盘 | C38: =VLOOKUP(D38,[2]品类分类!$F:$G,2,FALSE) -> 001700030001 | D38: 直线传动件 | E38: 001700030001 | F38: 产品量产>1年 | G38: 产品正在开发中 | H38: 没有类似产品
A39: 288 | B39: 标准啮合传动件-选型沙盘 | C39: =VLOOKUP(D39,[2]品类分类!$F:$G,2,FALSE) -> 001700030002 | D39: 标准啮合传动件 | E39: 001700030002 | F39: 产品量产>1年 | G39: 产品正在开发中 | H39: 没有类似产品
A40: 289 | B40: 带传动件-选型沙盘 | C40: =VLOOKUP(D40,[2]品类分类!$F:$G,2,FALSE) -> 001700030003 | D40: 带传动件 | E40: 001700030003 | F40: 产品量产>1年 | G40: 产品正在开发中 | H40: 没有类似产品
... A57: 314 | B57: 机加表面处理-能力地图 | C57: =VLOOKUP(D57,[2]品类分类!$F:$G,2,FALSE) -> 001800040001 | D57: 机加表面处理 | E57: 001800040001 | F57: ①加工迈瑞产品量产1年以上或②供应商TOP级客户同类产品完成2~16个项目； | G57: 加工迈瑞打样或量产产品13年以内，其能力未得到充分验证； | H57: 供应商有合作意愿，但技术能力不足以支撑，有待进一步成长；
A58: 316 | B58: 自制机加钣金工序外协-能力地图 | C58: =VLOOKUP(D58,[2]品类分类!$F:$G,2,FALSE) -> 001900020001 | D58: 自制机加钣金工序外协 | E58: 001900020001
A59: 317 | B59: 弹片-能力地图 | C59: =VLOOKUP(D59,[2]品类分类!$F:$G,2,FALSE) -> 001900030001 | D59: 弹片 | E59: 001900030001 | F59: ①加工迈瑞产品量产1年以上；②供应商客户同类产品加工2~4个项目； | G59: ①加工迈瑞打样或量产产品1年以内，其能力未得到充分验证； | H59: 供应商有合作意愿，但技术能力不足以支撑，有待进一步成长；
A60: 319 | B60: 洁净注塑-能力地图 | C60: =VLOOKUP(D60,[2]品类分类!$F:$G,2,FALSE) -> 002000010002 | D60: 洁净注塑 | E60: 002000010002 | F60: A: 已经具有量产1年以上经验 (迈瑞或同行业TOP级制造商） | G60: B:刚量产生产爬坡阶段 | H60: C：验证中或无生产过
A61: 320 | B61: 量产手板件-能力地图 | C61: =VLOOKUP(D61,[2]品类分类!$F:$G,2,FALSE) -> 002000010003 | D61: 量产手板件 | E61: 002000010003
...

Sheet 能力地图信息
A1: 地图ID | B1: 地图名称 | C1: 能力ID | D1: 一阶能力描述 | E1: 二阶能力描述 | F1: 三阶能力描述
A2: 227 | B2: CO/PICCO附件-选型沙盘 | C2: =A2&"001" -> 227001 | D2: 关键参数 | E2: 创伤性（微创） | F2: 创伤性（微创）
A3: 227 | B3: CO/PICCO附件-选型沙盘 | C3: =C2+1 -> 227002 | D3: 关键参数 | E3: 典型操作部位（颈静脉+股动脉） | F3: 典型操作部位（颈静脉+股动脉）
A4: 227 | B4: CO/PICCO附件-选型沙盘 | C4: =C3+1 -> 227003 | D4: 关键参数 | E4: 测量原理（经肺CO +_x000B_脉搏Contour图分析） | F4: 测量原理（经肺CO +_x000B_脉搏Contour图分析）
A5: 228 | B5: ICG/FLOTRAC附件-选型沙盘 | C5: =A5&"001" -> 228001 | D5: 关键参数 | E5: 创伤性（无创） | F5: 创伤性（无创）
A6: 228 | B6: ICG/FLOTRAC附件-选型沙盘 | C6: =C5+1 -> 228002 | D6: 关键参数 | E6: 创伤性（微创） | F6: 创伤性（微创）
A7: 228 | B7: ICG/FLOTRAC附件-选型沙盘 | C7: =C6+1 -> 228003 | D7: 关键参数 | E7: 典型操作部位（动脉） | F7: 典型操作部位（动脉）
A8: 228 | B8: ICG/FLOTRAC附件-选型沙盘 | C8: =C7+1 -> 228004 | D8: 关键参数 | E8: 典型操作部位（颈部和胸部皮肤外表面） | F8: 典型操作部位（颈部和胸部皮肤外表面）
A9: 228 | B9: ICG/FLOTRAC附件-选型沙盘 | C9: =C8+1 -> 228005 | D9: 关键参数 | E9: 测量原理（脉搏Contour图分析） | F9: 测量原理（脉搏Contour图分析）
A10: 228 | B10: ICG/FLOTRAC附件-选型沙盘 | C10: =C9+1 -> 228006 | D10: 关键参数 | E10: 测量原理（电阻抗法） | F10: 测量原理（电阻抗法）
A11: 229 | B11: 疼痛参数附件-选型沙盘 | C11: =A11&"001" -> 229001 | D11: 关键参数 | E11: 疼痛参数ANIi（0-100） | F11: 疼痛参数ANIi（0-100）
A12: 229 | B12: 疼痛参数附件-选型沙盘 | C12: =C11+1 -> 229002 | D12: 关键参数 | E12: 疼痛参数ANIm（0-100） | F12: 疼痛参数ANIm（0-100）
A13: 229 | B13: 疼痛参数附件-选型沙盘 | C13: =C12+1 -> 229003 | D13: 关键参数 | E13: 通讯接口RS232 | F13: 通讯接口RS232
A14: 229 | B14: 疼痛参数附件-选型沙盘 | C14: =C13+1 -> 229004 | D14: 关键参数 | E14: 典型操作部位（胸部） | F14: 典型操作部位（胸部）
A15: 230 | B15: CO2附件-选型沙盘 | C15: =A15&"001" -> 230001 | D15: 关键参数 | E15: 微流 | F15: 微流
A16: 230 | B16: CO2附件-选型沙盘 | C16: =C15+1 -> 230002 | D16: 关键参数 | E16: 主流 | F16: 主流
A17: 230 | B17: CO2附件-选型沙盘 | C17: =C16+1 -> 230003 | D17: 关键参数 | E17: 采样方式（气路采样） | F17: 采样方式（气路采样）
A18: 230 | B18: CO2附件-选型沙盘 | C18: =C17+1 -> 230004 | D18: 关键参数 | E18: 采样方式（鼻腔采样） | F18: 采样方式（鼻腔采样）
A19: 230 | B19: CO2附件-选型沙盘 | C19: =C18+1 -> 230005 | D19: 关键参数 | E19: 无创 | F19: 无创
A20: 230 | B20: CO2附件-选型沙盘 | C20: =C19+1 -> 230006 | D20: 销售区域 | E20: CE | F20: CE
A21: 230 | B21: CO2附件-选型沙盘 | C21: =C20+1 -> 230007 | D21: 销售区域 | E21: FDA | F21: FDA
A22: 230 | B22: CO2附件-选型沙盘 | C22: =C21+1 -> 230008 | D22: 销售区域 | E22: CFDA | F22: CFDA
A23: 230 | B23: CO2附件-选型沙盘 | C23: =C22+1 -> 230009 | D23: 适用人群 | E23: 新生儿 | F23: 新生儿
A24: 230 | B24: CO2附件-选型沙盘 | C24: =C23+1 -> 230010 | D24: 适用人群 | E24: 小儿 | F24: 小儿
A25: 230 | B25: CO2附件-选型沙盘 | C25: =C24+1 -> 230011 | D25: 适用人群 | E25: 成人 | F25: 成人
A26: 231 | B26: ISE电解质模块及附件-选型沙盘 | C26: =A26&"001" -> 231001 | D26: 关键参数(ISE模块) | E26: 间接法 | F26: 间接法
A27: 231 | B27: ISE电解质模块及附件-选型沙盘 | C27: =C26+1 -> 231002 | D27: 关键参数(ISE模块) | E27: 直接法 | F27: 直接法
A28: 231 | B28: ISE电解质模块及附件-选型沙盘 | C28: =C27+1 -> 231003 | D28: 关键参数(ISE模块) | E28: 测试速度（血清）（200样本/H） | F28: 测试速度（血清）（200样本/H）
A29: 231 | B29: ISE电解质模块及附件-选型沙盘 | C29: =C28+1 -> 231004 | D29: 关键参数(ISE模块) | E29: 测试速度（血清）（100样本/H） | F29: 测试速度（血清）（100样本/H）
A30: 231 | B30: ISE电解质模块及附件-选型沙盘 | C30: =C29+1 -> 231005 | D30: 关键参数(ISE模块) | E30: 测试速度（尿液）（133样本/H） | F30: 测试速度（尿液）（133样本/H）
A31: 231 | B31: ISE电解质模块及附件-选型沙盘 | C31: =C30+1 -> 231006 | D31: 关键参数(ISE模块) | E31: 测试速度（尿液）（60样本/H） | F31: 测试速度（尿液）（60样本/H）
A32: 231 | B32: ISE电解质模块及附件-选型沙盘 | C32: =C31+1 -> 231007 | D32: 关键参数(电极) | E32: Na,K有效期（12月） | F32: Na,K有效期（12月）
A33: 231 | B33: ISE电解质模块及附件-选型沙盘 | C33: =C32+1 -> 231008 | D33: 关键参数(电极) | E33: Na,K样本数量30000 | F33: Na,K样本数量30000
A34: 231 | B34: ISE电解质模块及附件-选型沙盘 | C34: =C33+1 -> 231009 | D34: 关键参数(电极) | E34: Na,K样本数量10000 | F34: Na,K样本数量10000
A35: 231 | B35: ISE电解质模块及附件-选型沙盘 | C35: =C34+1 -> 231010 | D35: 关键参数(电极) | E35: Cl有效期（12月） | F35: Cl有效期（12月）
A36: 231 | B36: ISE电解质模块及附件-选型沙盘 | C36: =C35+1 -> 231011 | D36: 关键参数(电极) | E36: Cl有效期（9月） | F36: Cl有效期（9月）
A37: 231 | B37: ISE电解质模块及附件-选型沙盘 | C37: =C36+1 -> 231012 | D37: 关键参数(电极) | E37: Cl样本数量30000 | F37: Cl样本数量30000
A38: 231 | B38: ISE电解质模块及附件-选型沙盘 | C38: =C37+1 -> 231013 | D38: 关键参数(电极) | E38: Cl样本数量10000 | F38: Cl样本数量10000
A39: 233 | B39: 探头声头附件-选型沙盘 | C39: =A39&"001" -> 233001 | D39: 脚踏开关 | E39: 无线脚踏开关 | F39: 单键
A40: 233 | B40: 探头声头附件-选型沙盘 | C40: =C39+1 -> 233002 | D40: 脚踏开关 | E40: 无线脚踏开关 | F40: 多键
...

Sheet 地图与制造商
A1: 地图ID | B1: 制造商编码 | C1: 制造商名称 | D1: 小品类
A2: 227 | B2: M01397 | C2: Pulsion | D2: =VLOOKUP(A2,能力地图!A:C,3,0) -> 001400020007
A3: 228 | B3: M00152 | C3: Edwards | D3: =VLOOKUP(A3,能力地图!A:C,3,0) -> 001400020008
A4: 228 | B4: M01691 | C4: Medis | D4: =VLOOKUP(A4,能力地图!A:C,3,0) -> 001400020008
A5: 229 | B5: M01995 | C5: Mdoloris | D5: =VLOOKUP(A5,能力地图!A:C,3,0) -> 001400020009
A6: 230 | B6: 潜在制造商 | C6: Medtronic | D6: =VLOOKUP(A6,能力地图!A:C,3,0) -> 001400020010
A7: 230 | B7: M01399 | C7: Respironic | D7: =VLOOKUP(A7,能力地图!A:C,3,0) -> 001400020010
A8: 231 | B8: M01329 | C8: A&T | D8: =VLOOKUP(A8,能力地图!A:C,3,0) -> 001400020011
A9: 231 | B9: M01515 | C9: 凯特 | D9: =VLOOKUP(A9,能力地图!A:C,3,0) -> 001400020011
A10: 231 | B10: M01379 | C10: Medica | D10: =VLOOKUP(A10,能力地图!A:C,3,0) -> 001400020011
A11: 233 | B11: M01938 | C11: 经方 | D11: =VLOOKUP(A11,能力地图!A:C,3,0) -> 001400030002
A12: 233 | B12: M02206 | C12: 立普 | D12: =VLOOKUP(A12,能力地图!A:C,3,0) -> 001400030002
A13: 233 | B13: M02245 | C13: 延顺 | D13: =VLOOKUP(A13,能力地图!A:C,3,0) -> 001400030002
... A273: 303 | B273: M-1700 | C273: 迈瑞机加中心 | D273: =VLOOKUP(A273,能力地图!A:C,3,0) -> 001800020001
A274: 221 | B274: 潜在制造商 | C274: Cardinal
A275: 221 | B275: M00919 | C275: 青岛光电
A276: 221 | B276: M01955 | C276: 英科
A277: 221 | B277: 潜在制造商 | C277: 3M
A278: 221 | B278: M01531 | C278: 美的连
A279: 221 | B279: M02135 | C279: Ambu
A280: 105 | B280: M01521 | C280: 立讯
A281: 105 | B281: M01519 | C281: 乐利
A282: 105 | B282: M02161 | C282: 卡莱
A283: 105 | B283: M01564 | C283: 泰嘉
A284: 105 | B284: M01487 | C284: 华展
A285: 105 | B285: M02294 | C285: 美博
... A310: 103 | B310: 潜在制造商 | C310: 43所

Sheet 能力值
A1: 地图ID | B1: 地图名称 | C1: 能力ID | D1: 三级能力描述 | E1: 制造商编码 | F1: 制造商名称 | G1: 能力值
A2: 227 | B2: CO/PICCO附件-选型沙盘 | C2: 227001 | D2: 创伤性（微创） | E2: M01397 | F2: Pulsion | G2: A
A3: 227 | B3: CO/PICCO附件-选型沙盘 | C3: 227002 | D3: 典型操作部位（颈静脉+股动脉） | E3: M01397 | F3: Pulsion | G3: A
A4: 227 | B4: CO/PICCO附件-选型沙盘 | C4: 227003 | D4: 测量原理（经肺CO +_x000B_脉搏Contour图分析） | E4: M01397 | F4: Pulsion | G4: A
A5: 228 | B5: ICG/FLOTRAC附件-选型沙盘 | C5: 228001 | D5: 创伤性（无创） | E5: M00152 | F5: Edwards | G5: C
A6: 228 | B6: ICG/FLOTRAC附件-选型沙盘 | C6: 228001 | D6: 创伤性（无创） | E6: M01691 | F6: Medis | G6: A
A7: 228 | B7: ICG/FLOTRAC附件-选型沙盘 | C7: 228002 | D7: 创伤性（微创） | E7: M00152 | F7: Edwards | G7: A
A8: 228 | B8: ICG/FLOTRAC附件-选型沙盘 | C8: 228002 | D8: 创伤性（微创） | E8: M01691 | F8: Medis | G8: C
A9: 228 | B9: ICG/FLOTRAC附件-选型沙盘 | C9: 228003 | D9: 典型操作部位（动脉） | E9: M00152 | F9: Edwards | G9: A
A10: 228 | B10: ICG/FLOTRAC附件-选型沙盘 | C10: 228003 | D10: 典型操作部位（动脉） | E10: M01691 | F10: Medis | G10: C
A11: 228 | B11: ICG/FLOTRAC附件-选型沙盘 | C11: 228004 | D11: 典型操作部位（颈部和胸部皮肤外表面） | E11: M00152 | F11: Edwards | G11: C
A12: 228 | B12: ICG/FLOTRAC附件-选型沙盘 | C12: 228004 | D12: 典型操作部位（颈部和胸部皮肤外表面） | E12: M01691 | F12: Medis | G12: A
A13: 228 | B13: ICG/FLOTRAC附件-选型沙盘 | C13: 228005 | D13: 测量原理（脉搏Contour图分析） | E13: M00152 | F13: Edwards | G13: A
A14: 228 | B14: ICG/FLOTRAC附件-选型沙盘 | C14: 228005 | D14: 测量原理（脉搏Contour图分析） | E14: M01691 | F14: Medis | G14: C
A15: 228 | B15: ICG/FLOTRAC附件-选型沙盘 | C15: 228006 | D15: 测量原理（电阻抗法） | E15: M00152 | F15: Edwards | G15: C
A16: 228 | B16: ICG/FLOTRAC附件-选型沙盘 | C16: 228006 | D16: 测量原理（电阻抗法） | E16: M01691 | F16: Medis | G16: A
A17: 229 | B17: 疼痛参数附件-选型沙盘 | C17: 229001 | D17: 疼痛参数ANIi（0-100） | E17: M01995 | F17: Mdoloris | G17: A
A18: 229 | B18: 疼痛参数附件-选型沙盘 | C18: 229002 | D18: 疼痛参数ANIm（0-100） | E18: M01995 | F18: Mdoloris | G18: A
A19: 229 | B19: 疼痛参数附件-选型沙盘 | C19: 229003 | D19: 通讯接口RS232 | E19: M01995 | F19: Mdoloris | G19: A
A20: 229 | B20: 疼痛参数附件-选型沙盘 | C20: 229004 | D20: 典型操作部位（胸部） | E20: M01995 | F20: Mdoloris | G20: A
A21: 230 | B21: CO2附件-选型沙盘 | C21: 230001 | D21: 微流 | E21: 潜在制造商 | F21: Medtronic | G21: A
A22: 230 | B22: CO2附件-选型沙盘 | C22: 230001 | D22: 微流 | E22: M01399 | F22: Respironic | G22: C
A23: 230 | B23: CO2附件-选型沙盘 | C23: 230002 | D23: 主流 | E23: 潜在制造商 | F23: Medtronic | G23: C
A24: 230 | B24: CO2附件-选型沙盘 | C24: 230002 | D24: 主流 | E24: M01399 | F24: Respironic | G24: A
A25: 230 | B25: CO2附件-选型沙盘 | C25: 230003 | D25: 采样方式（气路采样） | E25: 潜在制造商 | F25: Medtronic | G25: A
A26: 230 | B26: CO2附件-选型沙盘 | C26: 230003 | D26: 采样方式（气路采样） | E26: M01399 | F26: Respironic | G26: A
A27: 230 | B27: CO2附件-选型沙盘 | C27: 230004 | D27: 采样方式（鼻腔采样） | E27: 潜在制造商 | F27: Medtronic | G27: A
A28: 230 | B28: CO2附件-选型沙盘 | C28: 230004 | D28: 采样方式（鼻腔采样） | E28: M01399 | F28: Respironic | G28: C
A29: 230 | B29: CO2附件-选型沙盘 | C29: 230005 | D29: 无创 | E29: 潜在制造商 | F29: Medtronic | G29: A
A30: 230 | B30: CO2附件-选型沙盘 | C30: 230005 | D30: 无创 | E30: M01399 | F30: Respironic | G30: A
A31: 230 | B31: CO2附件-选型沙盘 | C31: 230006 | D31: CE | E31: 潜在制造商 | F31: Medtronic | G31: A
A32: 230 | B32: CO2附件-选型沙盘 | C32: 230006 | D32: CE | E32: M01399 | F32: Respironic | G32: A
A33: 230 | B33: CO2附件-选型沙盘 | C33: 230007 | D33: FDA | E33: 潜在制造商 | F33: Medtronic | G33: A
A34: 230 | B34: CO2附件-选型沙盘 | C34: 230007 | D34: FDA | E34: M01399 | F34: Respironic | G34: A
... A42: 230 | B42: CO2附件-选型沙盘 | C42: 230011 | D42: 成人 | E42: M01399 | F42: Respironic | G42: A
A43: 231 | B43: ISE电解质模块及附件-选型沙盘 | C43: 231001 | D43: 间接法 | E43: M01329 | F43: A&T | G43: A
A44: 231 | B44: ISE电解质模块及附件-选型沙盘 | C44: 231001 | D44: 间接法 | E44: M01515 | F44: 凯特 | G44: C
A45: 231 | B45: ISE电解质模块及附件-选型沙盘 | C45: 231001 | D45: 间接法 | E45: M01379 | F45: Medica | G45: C
A46: 231 | B46: ISE电解质模块及附件-选型沙盘 | C46: 231002 | D46: 直接法 | E46: M01329 | F46: A&T | G46: C
A47: 231 | B47: ISE电解质模块及附件-选型沙盘 | C47: 231002 | D47: 直接法 | E47: M01515 | F47: 凯特 | G47: A
...
